Workbook
Name _6345EXC: 'dust samples'!$A$8:$T$245
Name _MailAutoSig: 'isotope samples'!$G$9

Sheet Basic Information
A1: Core: Dye 2 (Raven) Greenland 1998 | E1: Core A
A2: Team: Ellen Mosley-Thompson, Victor Zagorodnov and Eric Klein
A3: The team arrived in the afternoon of May 11 and left on the afternoon of May 20.
A4: Two cores, 120.87 and 20.5 m were drilled. Core A (Core 1) was drilled first. The upper 20 meters was in very bad shape.
A5: The drill was adjusted and drilling continued to 120.87 m.
A6: The setup was moved slightly (less than a meter away) and a 20.5 meter core Core B (Core 2) was drilled to replace the upper 20 meters of Core A.
A8: Latitude | B8: 66.48 N
A9: Longitude | B9: 46.30 W
A10: Elevation | B10: ~2332 m
A11: Core A | B11: 120.87 m | C11: core bottom depth
A12: Core B | B12: 20.5 m | C12: core bottom depth

Sheet dust samples
A1: Core: Dye 2 (Raven) Greenland 1998 | E1: Core A
H2: Note: Concentrations per mL must be calculated using the sample volume analyzed: see Column T for the sample volume | T2: sample | AI2: coarseness
A3: Individual Sample Data: Microparticles | F3: Size distribution data | T3: volume | AI3: factor
T4: 2 = 50 uL | AI4: (> 1.00 / > 0.63)*100
A5: Date | B5: Section | C5: Sample | D5: Depth at top | E5: Sample Size | F5: 0.63 - 0.80 | G5: 0.8 - 1.0 | H5: 1.0 - 1.26 | I5: 1.26 - 1.59 | J5: 1.59 - 2.02 | K5: 2.02 - 2.52 | L5: 2.52 - 3.14 | M5: 3.14 - 4.0 | N5: 4.0 - 5.04 | O5: 5.04 - 6.35 | P5: 6.35 - 8.0 | Q5: 8.0 - 10.08 | R5: 10.08 - 12.7 | S5: 12.7 - 16.0 | T5: 0 = 500 uL | U5: > 0.63 | V5: > 0.8 | W5: > 1.0 | X5: > 1.26 | Y5: > 1.59 | Z5: > 2.02 | AA5: > 2.52 | AB5: > 3.14 | AC5: > 4.0 | AD5: > 5.04 | AE5: > 6.35 | AF5: > 8.0 | AG5: > 10.08 | AH5: > 12.7 | AI5: CF
A6: Analyzed | B6: Number | C6: Number | D6: m (firn) | E6: cm (firn) | T6: 1 = missing
A8: 110399 | B8: 19 | C8: 1 | D8: 18.65 | E8: 6.1 | F8: 109 | G8: 56 | H8: 31 | I8: 13 | J8: 3 | K8: 3 | L8: 2 | M8: 1 | N8: 1 | O8: 0 | P8: 0 | Q8: 0 | R8: 0 | S8: 0 | T8: 2 | U8: =SUM(F8:S8) -> 219 | V8: =SUM(G8:S8) -> 110 | W8: =SUM(H8:S8) -> 54 | X8: =SUM(I8:S8) -> 23 | Y8: =SUM(J8:S8) -> 10 | Z8: =SUM(K8:S8) -> 7 | AA8: =SUM(L8:S8) -> 4 | AB8: =SUM(M8:S8) -> 2 | AC8: =SUM(N8:S8) -> 1 | AD8: =SUM(O8:S8) -> 0 | AE8: =SUM(P8:S8) -> 0 | AF8: =SUM(Q8:S8) -> 0 | AG8: =SUM(R8:S8) -> 0 | AH8: =SUM(S8) -> 0 | AI8: =(W8/U8)*100 -> 24.657534
A9: 110399 | B9: 19 | C9: 2 | D9: 18.711 | E9: 5.1 | F9: 52 | G9: 32 | H9: 19 | I9: 13 | J9: 6 | K9: 3 | L9: 0 | M9: 2 | N9: 0 | O9: 1 | P9: 0 | Q9: 0 | R9: 1 | S9: 0 | T9: 2 | U9: =SUM(F9:S9) -> 129 | V9: =SUM(G9:S9) -> 77 | W9: =SUM(H9:S9) -> 45 | X9: =SUM(I9:S9) -> 26 | Y9: =SUM(J9:S9) -> 13 | Z9: =SUM(K9:S9) -> 7 | AA9: =SUM(L9:S9) -> 4 | AB9: =SUM(M9:S9) -> 4 | AC9: =SUM(N9:S9) -> 2 | AD9: =SUM(O9:S9) -> 2 | AE9: =SUM(P9:S9) -> 1 | AF9: =SUM(Q9:S9) -> 1 | AG9: =SUM(R9:S9) -> 1 | AH9: =SUM(S9) -> 0 | AI9: =(W9/U9)*100 -> 34.883721
A10: 110399 | B10: 19 | C10: 3 | D10: 18.762 | E10: 5.1 | F10: 139 | G10: 58 | H10: 38 | I10: 16 | J10: 5 | K10: 4 | L10: 2 | M10: 0 | N10: 0 | O10: 0 | P10: 0 | Q10: 1 | R10: 1 | S10: 0 | T10: 2 | U10: =SUM(F10:S10) -> 264 | V10: =SUM(G10:S10) -> 125 | W10: =SUM(H10:S10) -> 67 | X10: =SUM(I10:S10) -> 29 | Y10: =SUM(J10:S10) -> 13 | Z10: =SUM(K10:S10) -> 8 | AA10: =SUM(L10:S10) -> 4 | AB10: =SUM(M10:S10) -> 2 | AC10: =SUM(N10:S10) -> 2 | AD10: =SUM(O10:S10) -> 2 | AE10: =SUM(P10:S10) -> 2 | AF10: =SUM(Q10:S10) -> 2 | AG10: =SUM(R10:S10) -> 1 | AH10: =SUM(S10) -> 0 | AI10: =(W10/U10)*100 -> 25.378788
A11: 110399 | B11: 19 | C11: 4 | D11: 18.813 | E11: 5.1 | F11: 73 | G11: 37 | H11: 18 | I11: 14 | J11: 4 | K11: 1 | L11: 1 | M11: 0 | N11: 0 | O11: 0 | P11: 0 | Q11: 0 | R11: 0 | S11: 0 | T11: 2 | U11: =SUM(F11:S11) -> 148 | V11: =SUM(G11:S11) -> 75 | W11: =SUM(H11:S11) -> 38 | X11: =SUM(I11:S11) -> 20 | Y11: =SUM(J11:S11) -> 6 | Z11: =SUM(K11:S11) -> 2 | AA11: =SUM(L11:S11) -> 1 | AB11: =SUM(M11:S11) -> 0 | AC11: =SUM(N11:S11) -> 0 | AD11: =SUM(O11:S11) -> 0 | AE11: =SUM(P11:S11) -> 0 | AF11: =SUM(Q11:S11) -> 0 | AG11: =SUM(R11:S11) -> 0 | AH11: =SUM(S11) -> 0 | AI11: =(W11/U11)*100 -> 25.675676
A12: 110399 | B12: 19 | C12: 5 | D12: 18.864 | E12: 5.1 | F12: 84 | G12: 34 | H12: 28 | I12: 12 | J12: 6 | K12: 2 | L12: 3 | M12: 1 | N12: 0 | O12: 0 | P12: 0 | Q12: 0 | R12: 0 | S12: 0 | T12: 2 | U12: =SUM(F12:S12) -> 170 | V12: =SUM(G12:S12) -> 86 | W12: =SUM(H12:S12) -> 52 | X12: =SUM(I12:S12) -> 24 | Y12: =SUM(J12:S12) -> 12 | Z12: =SUM(K12:S12) -> 6 | AA12: =SUM(L12:S12) -> 4 | AB12: =SUM(M12:S12) -> 1 | AC12: =SUM(N12:S12) -> 0 | AD12: =SUM(O12:S12) -> 0 | AE12: =SUM(P12:S12) -> 0 | AF12: =SUM(Q12:S12) -> 0 | AG12: =SUM(R12:S12) -> 0 | AH12: =SUM(S12) -> 0 | AI12: =(W12/U12)*100 -> 30.588235
A13: 110399 | B13: 19 | C13: 6 | D13: 18.915 | E13: 5.1 | F13: 66 | G13: 26 | H13: 14 | I13: 14 | J13: 8 | K13: 3 | L13: 0 | M13: 1 | N13: 1 | O13: 0 | P13: 0 | Q13: 0 | R13: 0 | S13: 0 | T13: 2 | U13: =SUM(F13:S13) -> 133 | V13: =SUM(G13:S13) -> 67 | W13: =SUM(H13:S13) -> 41 | X13: =SUM(I13:S13) -> 27 | Y13: =SUM(J13:S13) -> 13 | Z13: =SUM(K13:S13) -> 5 | AA13: =SUM(L13:S13) -> 2 | AB13: =SUM(M13:S13) -> 2 | AC13: =SUM(N13:S13) -> 1 | AD13: =SUM(O13:S13) -> 0 | AE13: =SUM(P13:S13) -> 0 | AF13: =SUM(Q13:S13) -> 0 | AG13: =SUM(R13:S13) -> 0 | AH13: =SUM(S13) -> 0 | AI13: =(W13/U13)*100 -> 30.827068
A14: 110399 | B14: 19 | C14: 7 | D14: 18.966 | E14: 5.1 | F14: 60 | G14: 39 | H14: 18 | I14: 15 | J14: 8 | K14: 1 | L14: 1 | M14: 2 | N14: 0 | O14: 0 | P14: 1 | Q14: 0 | R14: 0 | S14: 0 | T14: 2 | U14: =SUM(F14:S14) -> 145 | V14: =SUM(G14:S14) -> 85 | W14: =SUM(H14:S14) -> 46 | X14: =SUM(I14:S14) -> 28 | Y14: =SUM(J14:S14) -> 13 | Z14: =SUM(K14:S14) -> 5 | AA14: =SUM(L14:S14) -> 4 | AB14: =SUM(M14:S14) -> 3 | AC14: =SUM(N14:S14) -> 1 | AD14: =SUM(O14:S14) -> 1 | AE14: =SUM(P14:S14) -> 1 | AF14: =SUM(Q14:S14) -> 0 | AG14: =SUM(R14:S14) -> 0 | AH14: =SUM(S14) -> 0 | AI14: =(W14/U14)*100 -> 31.724138
A15: 110399 | B15: 19 | C15: 8 | D15: 19.017 | E15: 5.1 | F15: 86 | G15: 36 | H15: 15 | I15: 3 | J15: 2 | K15: 1 | L15: 0 | M15: 0 | N15: 0 | O15: 0 | P15: 0 | Q15: 0 | R15: 0 | S15: 0 | T15: 2 | U15: =SUM(F15:S15) -> 143 | V15: =SUM(G15:S15) -> 57 | W15: =SUM(H15:S15) -> 21 | X15: =SUM(I15:S15) -> 6 | Y15: =SUM(J15:S15) -> 3 | Z15: =SUM(K15:S15) -> 1 | AA15: =SUM(L15:S15) -> 0 | AB15: =SUM(M15:S15) -> 0 | AC15: =SUM(N15:S15) -> 0 | AD15: =SUM(O15:S15) -> 0 | AE15: =SUM(P15:S15) -> 0 | AF15: =SUM(Q15:S15) -> 0 | AG15: =SUM(R15:S15) -> 0 | AH15: =SUM(S15) -> 0 | AI15: =(W15/U15)*100 -> 14.685315
A16: 110399 | B16: 19 | C16: 9 | D16: 19.068 | E16: 5.1 | F16: 115 | G16: 38 | H16: 25 | I16: 9 | J16: 6 | K16: 0 | L16: 1 | M16: 0 | N16: 1 | O16: 0 | P16: 0 | Q16: 0 | R16: 0 | S16: 0 | T16: 2 | U16: =SUM(F16:S16) -> 195 | V16: =SUM(G16:S16) -> 80 | W16: =SUM(H16:S16) -> 42 | X16: =SUM(I16:S16) -> 17 | Y16: =SUM(J16:S16) -> 8 | Z16: =SUM(K16:S16) -> 2 | AA16: =SUM(L16:S16) -> 2 | AB16: =SUM(M16:S16) -> 1 | AC16: =SUM(N16:S16) -> 1 | AD16: =SUM(O16:S16) -> 0 | AE16: =SUM(P16:S16) -> 0 | AF16: =SUM(Q16:S16) -> 0 | AG16: =SUM(R16:S16) -> 0 | AH16: =SUM(S16) -> 0 | AI16: =(W16/U16)*100 -> 21.538462
A17: 110399 | B17: 19 | C17: 10 | D17: 19.119 | E17: 5.1 | F17: 167 | G17: 58 | H17: 20 | I17: 7 | J17: 2 | K17: 0 | L17: 0 | M17: 3 | N17: 1 | O17: 0 | P17: 0 | Q17: 0 | R17: 0 | S17: 0 | T17: 2 | U17: =SUM(F17:S17) -> 258 | V17: =SUM(G17:S17) -> 91 | W17: =SUM(H17:S17) -> 33 | X17: =SUM(I17:S17) -> 13 | Y17: =SUM(J17:S17) -> 6 | Z17: =SUM(K17:S17) -> 4 | AA17: =SUM(L17:S17) -> 4 | AB17: =SUM(M17:S17) -> 4 | AC17: =SUM(N17:S17) -> 1 | AD17: =SUM(O17:S17) -> 0 | AE17: =SUM(P17:S17) -> 0 | AF17: =SUM(Q17:S17) -> 0 | AG17: =SUM(R17:S17) -> 0 | AH17: =SUM(S17) -> 0 | AI17: =(W17/U17)*100 -> 12.790698
A18: 110399 | B18: 19 | C18: 11 | D18: 19.17 | E18: 5 | F18: 195 | G18: 59 | H18: 29 | I18: 19 | J18: 4 | K18: 5 | L18: 0 | M18: 0 | N18: 0 | O18: 0 | P18: 0 | Q18: 0 | R18: 0 | S18: 0 | T18: 2 | U18: =SUM(F18:S18) -> 311 | V18: =SUM(G18:S18) -> 116 | W18: =SUM(H18:S18) -> 57 | X18: =SUM(I18:S18) -> 28 | Y18: =SUM(J18:S18) -> 9 | Z18: =SUM(K18:S18) -> 5 | AA18: =SUM(L18:S18) -> 0 | AB18: =SUM(M18:S18) -> 0 | AC18: =SUM(N18:S18) -> 0 | AD18: =SUM(O18:S18) -> 0 | AE18: =SUM(P18:S18) -> 0 | AF18: =SUM(Q18:S18) -> 0 | AG18: =SUM(R18:S18) -> 0 | AH18: =SUM(S18) -> 0 | AI18: =(W18/U18)*100 -> 18.327974
A19: 110399 | B19: 19 | C19: 12 | D19: 19.22 | E19: 5 | F19: 141 | G19: 48 | H19: 28 | I19: 14 | J19: 8 | K19: 2 | L19: 0 | M19: 0 | N19: 1 | O19: 0 | P19: 0 | Q19: 0 | R19: 0 | S19: 0 | T19: 2 | U19: =SUM(F19:S19) -> 242 | V19: =SUM(G19:S19) -> 101 | W19: =SUM(H19:S19) -> 53 | X19: =SUM(I19:S19) -> 25 | Y19: =SUM(J19:S19) -> 11 | Z19: =SUM(K19:S19) -> 3 | AA19: =SUM(L19:S19) -> 1 | AB19: =SUM(M19:S19) -> 1 | AC19: =SUM(N19:S19) -> 1 | AD19: =SUM(O19:S19) -> 0 | AE19: =SUM(P19:S19) -> 0 | AF19: =SUM(Q19:S19) -> 0 | AG19: =SUM(R19:S19) -> 0 | AH19: =SUM(S19) -> 0 | AI19: =(W19/U19)*100 -> 21.900826
... A1500: 20699 | B1500: 90 | C1500: 20 | D1500: 91.6 | E1500: 5 | F1500: 88 | G1500: 59 | H1500: 37 | I1500: 17 | J1500: 19 | K1500: 13 | L1500: 1 | M1500: 4 | N1500: 0 | O1500: 0 | P1500: 0 | Q1500: 0 | R1500: 0 | S1500: 0 | T1500: 2 | U1500: =SUM(F1500:S1500) -> 238 | V1500: =SUM(G1500:S1500) -> 150 | W1500: =SUM(H1500:S1500) -> 91 | X1500: =SUM(I1500:S1500) -> 54 | Y1500: =SUM(J1500:S1500) -> 37 | Z1500: =SUM(K1500:S1500) -> 18 | AA1500: =SUM(L1500:S1500) -> 5 | AB1500: =SUM(M1500:S1500) -> 4 | AC1500: =SUM(N1500:S1500) -> 0 | AD1500: =SUM(O1500:S1500) -> 0 | AE1500: =SUM(P1500:S1500) -> 0 | AF1500: =SUM(Q1500:S1500) -> 0 | AG1500: =SUM(R1500:S1500) -> 0 | AH1500: =SUM(S1500) -> 0 | AI1500: =(W1500/U1500)*100 -> 38.235294
A1501: 112000 | B1501: 91 | C1501: 1 | D1501: 91.65 | E1501: 6 | F1501: 161 | G1501: 89 | H1501: 64 | I1501: 27 | J1501: 8 | K1501: 3 | L1501: 1 | M1501: 1 | N1501: 1 | O1501: 0 | P1501: 0 | Q1501: 0 | R1501: 0 | S1501: 0 | T1501: 2 | U1501: 355 | V1501: 194 | W1501: 105 | X1501: 41 | Y1501: 14 | Z1501: 6 | AA1501: 3 | AB1501: 2 | AC1501: 1 | AD1501: 0 | AE1501: 0 | AF1501: 0 | AG1501: 0 | AH1501: 0 | AI1501: 29.58
A1502: 112000 | B1502: 91 | C1502: 2 | D1502: 91.71 | E1502: 5.9 | F1502: 159 | G1502: 85 | H1502: 59 | I1502: 26 | J1502: 12 | K1502: 5 | L1502: 1 | M1502: 0 | N1502: 0 | O1502: 0 | P1502: 1 | Q1502: 0 | R1502: 0 | S1502: 0 | T1502: 2 | U1502: 348 | V1502: 189 | W1502: 104 | X1502: 45 | Y1502: 19 | Z1502: 7 | AA1502: 2 | AB1502: 1 | AC1502: 1 | AD1502: 1 | AE1502: 1 | AF1502: 0 | AG1502: 0 | AH1502: 0 | AI1502: 29.89
A1503: 112000 | B1503: 91 | C1503: 3 | D1503: 91.769 | E1503: 5.9 | F1503: 88 | G1503: 39 | H1503: 19 | I1503: 19 | J1503: 6 | K1503: 4 | L1503: 2 | M1503: 1 | N1503: 0 | O1503: 0 | P1503: 0 | Q1503: 1 | R1503: 0 | S1503: 0 | T1503: 2 | U1503: 179 | V1503: 91 | W1503: 52 | X1503: 33 | Y1503: 14 | Z1503: 8 | AA1503: 4 | AB1503: 2 | AC1503: 1 | AD1503: 1 | AE1503: 1 | AF1503: 1 | AG1503: 0 | AH1503: 0 | AI1503: 29.05
A1504: 112000 | B1504: 91 | C1504: 4 | D1504: 91.828 | E1504: 5.9 | F1504: 412 | G1504: 223 | H1504: 155 | I1504: 78 | J1504: 30 | K1504: 11 | L1504: 8 | M1504: 2 | N1504: 2 | O1504: 0 | P1504: 0 | Q1504: 0 | R1504: 0 | S1504: 0 | T1504: 2 | U1504: 921 | V1504: 509 | W1504: 286 | X1504: 131 | Y1504: 53 | Z1504: 23 | AA1504: 12 | AB1504: 4 | AC1504: 2 | AD1504: 0 | AE1504: 0 | AF1504: 0 | AG1504: 0 | AH1504: 0 | AI1504: 31.05
A1505: 112000 | B1505: 91 | C1505: 5 | D1505: 91.887 | E1505: 5.9 | F1505: 445 | G1505: 304 | H1505: 215 | I1505: 88 | J1505: 33 | K1505: 10 | L1505: 3 | M1505: 3 | N1505: 2 | O1505: 0 | P1505: 0 | Q1505: 0 | R1505: 0 | S1505: 1 | T1505: 2 | U1505: 1104 | V1505: 659 | W1505: 355 | X1505: 140 | Y1505: 52 | Z1505: 19 | AA1505: 9 | AB1505: 6 | AC1505: 3 | AD1505: 1 | AE1505: 1 | AF1505: 1 | AG1505: 1 | AH1505: 1 | AI1505: 32.16
A1506: 112000 | B1506: 91 | C1506: 6 | D1506: 91.946 | E1506: 5.9 | F1506: 165 | G1506: 79 | H1506: 63 | I1506: 21 | J1506: 11 | K1506: 3 | L1506: 4 | M1506: 0 | N1506: 1 | O1506: 2 | P1506: 0 | Q1506: 0 | R1506: 0 | S1506: 0 | T1506: 2 | U1506: 349 | V1506: 184 | W1506: 105 | X1506: 42 | Y1506: 21 | Z1506: 10 | AA1506: 7 | AB1506: 3 | AC1506: 3 | AD1506: 2 | AE1506: 0 | AF1506: 0 | AG1506: 0 | AH1506: 0 | AI1506: 30.09
A1507: 112000 | B1507: 91 | C1507: 7 | D1507: 92.005 | E1507: 5.9 | F1507: 77 | G1507: 41 | H1507: 16 | I1507: 13 | J1507: 3 | K1507: 2 | L1507: 1 | M1507: 0 | N1507: 0 | O1507: 0 | P1507: 1 | Q1507: 1 | R1507: 0 | S1507: 0 | T1507: 2 | U1507: 155 | V1507: 78 | W1507: 37 | X1507: 21 | Y1507: 8 | Z1507: 5 | AA1507: 3 | AB1507: 2 | AC1507: 2 | AD1507: 2 | AE1507: 2 | AF1507: 1 | AG1507: 0 | AH1507: 0 | AI1507: 23.87
A1508: 112000 | B1508: 91 | C1508: 8 | D1508: 92.064 | E1508: 5.9 | F1508: 96 | G1508: 38 | H1508: 20 | I1508: 10 | J1508: 5 | K1508: 2 | L1508: 1 | M1508: 0 | N1508: 0 | O1508: 1 | P1508: 0 | Q1508: 0 | R1508: 0 | S1508: 0 | T1508: 2 | U1508: 173 | V1508: 77 | W1508: 39 | X1508: 19 | Y1508: 9 | Z1508: 4 | AA1508: 2 | AB1508: 1 | AC1508: 1 | AD1508: 1 | AE1508: 0 | AF1508: 0 | AG1508: 0 | AH1508: 0 | AI1508: 22.54
A1509: 112000 | B1509: 91 | C1509: 9 | D1509: 92.123 | E1509: 5.9 | F1509: 203 | G1509: 125 | H1509: 77 | I1509: 41 | J1509: 13 | K1509: 7 | L1509: 3 | M1509: 0 | N1509: 1 | O1509: 0 | P1509: 0 | Q1509: 0 | R1509: 0 | S1509: 0 | T1509: 2 | U1509: 470 | V1509: 267 | W1509: 142 | X1509: 65 | Y1509: 24 | Z1509: 11 | AA1509: 4 | AB1509: 1 | AC1509: 1 | AD1509: 0 | AE1509: 0 | AF1509: 0 | AG1509: 0 | AH1509: 0 | AI1509: 30.21
A1510: 112000 | B1510: 91 | C1510: 10 | D1510: 92.182 | E1510: 5.9 | F1510: 59 | G1510: 48 | H1510: 26 | I1510: 14 | J1510: 3 | K1510: 2 | L1510: 0 | M1510: 0 | N1510: 0 | O1510: 0 | P1510: 0 | Q1510: 0 | R1510: 0 | S1510: 0 | T1510: 2 | U1510: 152 | V1510: 93 | W1510: 45 | X1510: 19 | Y1510: 5 | Z1510: 2 | AA1510: 0 | AB1510: 0 | AC1510: 0 | AD1510: 0 | AE1510: 0 | AF1510: 0 | AG1510: 0 | AH1510: 0 | AI1510: 29.61
A1511: 112000 | B1511: 91 | C1511: 11 | D1511: 92.241 | E1511: 5.9 | F1511: 219 | G1511: 166 | H1511: 104 | I1511: 82 | J1511: 52 | K1511: 32 | L1511: 17 | M1511: 5 | N1511: 6 | O1511: 2 | P1511: 0 | Q1511: 2 | R1511: 0 | S1511: 1 | T1511: 2 | U1511: 688 | V1511: 469 | W1511: 303 | X1511: 199 | Y1511: 117 | Z1511: 65 | AA1511: 33 | AB1511: 16 | AC1511: 11 | AD1511: 5 | AE1511: 3 | AF1511: 3 | AG1511: 1 | AH1511: 1 | AI1511: 44.04
A1512: 112000 | B1512: 91 | C1512: 12 | D1512: 92.3 | E1512: 5.8 | F1512: 239 | G1512: 196 | H1512: 125 | I1512: 58 | J1512: 30 | K1512: 14 | L1512: 5 | M1512: 0 | N1512: 2 | O1512: 0 | P1512: 0 | Q1512: 2 | R1512: 0 | S1512: 0 | T1512: 2 | U1512: 671 | V1512: 432 | W1512: 236 | X1512: 111 | Y1512: 53 | Z1512: 23 | AA1512: 9 | AB1512: 4 | AC1512: 4 | AD1512: 2 | AE1512: 2 | AF1512: 2 | AG1512: 0 | AH1512: 0 | AI1512: 35.17
... A2041: 121799 | B2041: 120 | C2041: 5 | D2041: 120.125 | E2041: 4.6 | F2041: 123 | G2041: 93 | H2041: 61 | I2041: 38 | J2041: 19 | K2041: 8 | L2041: 3 | M2041: 1 | N2041: 0 | O2041: 0 | P2041: 0 | Q2041: 0 | R2041: 0 | S2041: 0 | T2041: 2 | U2041: 346 | V2041: 223 | W2041: 130 | X2041: 69 | Y2041: 31 | Z2041: 12 | AA2041: 4 | AB2041: 1 | AC2041: 0 | AD2041: 0 | AE2041: 0 | AF2041: 0 | AG2041: 0 | AH2041: 0 | AI2041: 37.57

Sheet isotope samples
A1: Core: Dye 2 (Raven) Greenland 1998 | E1: Core A | G1: NM = not measured
A2: Individual Sample Data: O18 | G2: NC = not calculated
A4: Date | B4: Section | C4: Sample | D4: Depth at top | E4: Sample Size | F4: O18 | G4: D | H4: D-excess
A5: Analyzed | B5: Number | C5: Number | D5: m (firn) | E5: cm (firn) | G5: NM | H5: NC
A6: 110399 | B6: 19 | C6: 1 | D6: 18.65 | E6: 6.1 | F6: -23.18
A7: 110399 | B7: 19 | C7: 2 | D7: 18.711 | E7: 5.1 | F7: -22.92
A8: 110399 | B8: 19 | C8: 3 | D8: 18.762 | E8: 5.1 | F8: -24.68
A9: 110399 | B9: 19 | C9: 4 | D9: 18.813 | E9: 5.1 | F9: -24.23
A10: 110399 | B10: 19 | C10: 5 | D10: 18.864 | E10: 5.1 | F10: -24.8
A11: 110399 | B11: 19 | C11: 6 | D11: 18.915 | E11: 5.1 | F11: -24.85
A12: 110399 | B12: 19 | C12: 7 | D12: 18.966 | E12: 5.1 | F12: -25.67
A13: 110399 | B13: 19 | C13: 8 | D13: 19.017 | E13: 5.1 | F13: -26.38
A14: 110399 | B14: 19 | C14: 9 | D14: 19.068 | E14: 5.1 | F14: -27.47
A15: 110399 | B15: 19 | C15: 10 | D15: 19.119 | E15: 5.1 | F15: -27.37
A16: 110399 | B16: 19 | C16: 11 | D16: 19.17 | E16: 5 | F16: -26.9
A17: 110399 | B17: 19 | C17: 12 | D17: 19.22 | E17: 5 | F17: -24.82
... A2039: 121799 | B2039: 120 | C2039: 5 | D2039: 120.125 | E2039: 4.6 | F2039: -23.09
D2040: =D2039+E2039 -> 124.725

Sheet dating file
A1: Core: Dye 2 (Raven) Greenland 1998 | E1: Core A
A3: Core A | B3: Core depth | C3: final dating | E3: Depth firn | F3: Core depth | G3: isotopes
B4: water eq | C4: dust | D4: years top | E4: (m) | F4: (m w.e.) | J4: Dust | K4: dust | O4: O18 | P4: O18
A5: depth m | B5: final | C5: > 0.63 (1000) | J5: Depth at top | K5: Depth at top | L5: dust | M5: accum (m w.e.) | N5: no samples | O5: Depth at top | P5: Depth at top | Q5: year | R5: accum (m w.e.) | S5: no samples
A6: 18.65 | B6: 10.012 | C6: 4.38 | E6: 18.65 | F6: 10.012 | G6: -23.18 | J6: (m) | K6: (m w.e.) | L6: year | M6: dust | O6: (m) | P6: (m w.e.) | R6: O18 (m)
A7: 18.711 | B7: 10.050826 | C7: 2.58 | E7: 18.711 | F7: 10.050826 | G7: -22.92 | J7: 19.95 | K7: 10.909356 | L7: 1969 | M7: 0.42814552 | N7: 10 | O7: 20.015 | P7: 10.951378 | Q7: 1969 | R7: 0.34056163 | S7: 8
A8: 18.762 | B8: 10.083309 | C8: 5.28 | E8: 18.762 | F8: 10.083309 | G8: -24.68 | J8: 20.61 | K8: 11.337501 | L8: 1968 | M8: 0.28720221 | N8: 8 | O8: 20.54 | P8: 11.29194 | Q8: 1968 | R8: 0.3327638 | S8: 9
A9: 18.813 | B9: 10.179486 | C9: 2.96 | E9: 18.813 | F9: 10.179486 | G9: -24.23 | J9: 21.05 | K9: 11.624704 | L9: 1967 | M9: 0.37411903 | N9: 11 | O9: 21.05 | P9: 11.624704 | Q9: 1967 | R9: 0.242587 | S9: 7
A10: 18.864 | B10: 10.21201 | C10: 3.4 | E10: 18.864 | F10: 10.21201 | G10: -24.8 | J10: 21.62 | K10: 11.998823 | L10: 1966 | M10: 0.42277766 | N10: 12 | O10: 21.42 | P10: 11.867291 | Q10: 1966 | R10: 0.51455412 | S10: 15
A11: 18.915 | B11: 10.244555 | C11: 2.66 | E11: 18.915 | F11: 10.244555 | G11: -24.85 | J11: 22.26 | K11: 12.4216 | L11: 1965 | M11: 0.30494123 | N11: 9 | O11: 22.2 | P11: 12.381845 | Q11: 1965 | R11: 0.27680876 | S11: 8
A12: 18.966 | B12: 10.27712 | C12: 2.9 | E12: 18.966 | F12: 10.27712 | G12: -25.67 | J12: 22.719 | K12: 12.726542 | L12: 1964 | M12: 0.34784723 | N12: 10 | O12: 22.617 | P12: 12.658654 | Q12: 1964 | R12: 0.31540227 | S12: 9
A13: 19.017 | B13: 10.309705 | C13: 2.86 | E13: 19.017 | F13: 10.309705 | G13: -26.38 | J13: 23.24 | K13: 13.074389 | L13: 1963 | M13: 0.27096588 | N13: 8 | O13: 23.09 | P13: 12.974056 | Q13: 1963 | R13: 0.37129888 | S13: 11
A14: 19.068 | B14: 10.342311 | C14: 3.9 | E14: 19.068 | F14: 10.342311 | G14: -27.47 | J14: 23.644 | K14: 13.345355 | L14: 1962 | M14: 0.33074329 | N14: 10 | O14: 23.644 | P14: 13.345355 | Q14: 1962 | R14: 0.20392109 | S14: 6
A15: 19.119 | B15: 10.374936 | C15: 5.16 | E15: 19.119 | F15: 10.374936 | G15: -27.37 | J15: 24.135 | K15: 13.676098 | L15: 1961 | M15: 0.44564325 | N15: 14 | O15: 23.947 | P15: 13.549276 | Q15: 1961 | R15: 0.4129942 | S15: 13
A16: 19.17 | B16: 10.407582 | C16: 6.22 | E16: 19.17 | F16: 10.407582 | G16: -26.9 | J16: 24.793 | K16: 14.121741 | L16: 1960 | M16: 0.23610272 | N16: 7 | O16: 24.558 | P16: 13.96227 | Q16: 1960 | R16: 0.26484287 | S16: 8
A17: 19.22 | B17: 10.439608 | C17: 4.84 | E17: 19.22 | F17: 10.439608 | G17: -24.82 | J17: 25.14 | K17: 14.357844 | L17: 1959 | M17: 0.13095789 | N17: 4 | O17: 24.948 | P17: 14.227113 | Q17: 1959 | R17: 0.16344937 | S17: 5
A18: 19.27 | B18: 10.471652 | C18: 4.06 | E18: 19.27 | F18: 10.471652 | G18: -24.78 | J18: 25.332 | K18: 14.488802 | L18: 1958 | M18: 0.098366316 | N18: 3 | O18: 25.188 | P18: 14.390562 | Q18: 1958 | R18: 0.098239615 | S18: 3
... A29: 19.895 | B29: 10.873823 | C29: 3.24 | E29: 19.895 | F29: 10.873823 | G29: -26.96 | J29: 30.098 | K29: 17.808131 | L29: 1947 | M29: 0.30701345 | N29: 9 | O29: 30.098 | P29: 17.808131 | Q29: 1947 | R29: 0.23870465 | S29: 7
A30: 19.95 | B30: 10.909356 | C30: 6.18 | D30: 1969 | E30: 19.95 | F30: 10.909356 | G30: -27 | J30: 30.53 | K30: 18.115145 | L30: 1946 | M30: 0.47376261 | N30: 13 | O30: 30.434 | P30: 18.046836 | Q30: 1946 | R30: 0.47343675 | S30: 13
A31: 20.015 | B31: 10.951378 | C31: 10.72 | E31: 20.015 | F31: 10.951378 | G31: -23.26 | H31: 1969 | J31: 31.194 | K31: 18.588907 | L31: 1945 | M31: 0.46018552 | N31: 13 | O31: 31.098 | P31: 18.520273 | Q31: 1945 | R31: 0.41250415 | S31: 12
A32: 20.08 | B32: 10.993432 | C32: 83 | E32: 20.08 | F32: 10.993432 | G32: -23.32 | J32: 31.836 | K32: 19.049093 | L32: 1944 | M32: 0.21646338 | N32: 6 | O32: 31.674 | P32: 18.932777 | Q32: 1944 | R32: 0.29175366 | S32: 8
A33: 20.145 | B33: 11.035517 | C33: 61.54 | E33: 20.145 | F33: 11.035517 | G33: -23.45 | J33: 32.137 | K33: 19.265556 | L33: 1943 | M33: 0.30711792 | N33: 9 | O33: 32.08 | P33: 19.22453 | Q33: 1943 | R33: 0.27813509 | S33: 8
A34: 20.205 | B34: 11.074393 | C34: 13.22 | E34: 20.205 | F34: 11.074393 | G34: -23.87 | J34: 32.563 | K34: 19.572674 | L34: 1942 | M34: 0.39564361 | N34: 11 | O34: 32.466 | P34: 19.502665 | Q34: 1942 | R34: 0.35629015 | S34: 10
A35: 20.27 | B35: 11.116539 | C35: 6.26 | E35: 20.27 | F35: 11.116539 | G35: -24.88 | J35: 33.11 | K35: 19.968318 | L35: 1941 | M35: 0.24809732 | N35: 7 | O35: 32.959 | P35: 19.858956 | Q35: 1941 | R35: 0.32333108 | S35: 9
A36: 20.34 | B36: 11.161962 | C36: 8.72 | E36: 20.34 | F36: 11.161962 | G36: -28.13 | J36: 33.452 | K36: 20.216415 | L36: 1940 | M36: 0.42930647 | N36: 12 | O36: 33.405 | P36: 20.182287 | Q36: 1940 | R36: 0.32646096 | S36: 9
A37: 20.405 | B37: 11.204172 | C37: 5.5 | E37: 20.405 | F37: 11.204172 | G37: -29.11 | J37: 34.042 | K37: 20.645721 | L37: 1939 | M37: 0.29417492 | N37: 8 | O37: 33.854 | P37: 20.508748 | Q37: 1939 | R37: 0.39680162 | S37: 11
A38: 20.47 | B38: 11.246414 | C38: 3.26 | E38: 20.47 | F38: 11.246414 | G38: -29.27 | J38: 34.445 | K38: 20.939896 | L38: 1938 | M38: 0.29419346 | N38: 8 | O38: 34.398 | P38: 20.905549 | Q38: 1938 | R38: 0.25968248 | S38: 7
A39: 20.54 | B39: 11.29194 | C39: 2.68 | E39: 20.54 | F39: 11.29194 | G39: -25.97 | H39: 1968 | J39: 34.847 | K39: 21.23409 | L39: 1937 | M39: 0.20755062 | N39: 6 | O39: 34.753 | P39: 21.165232 | Q39: 1937 | R39: 0.23604341 | S39: 7
A40: 20.61 | B40: 11.337501 | C40: 8.34 | D40: 1968 | E40: 20.61 | F40: 11.337501 | G40: -25.55 | J40: 35.13 | K40: 21.44164 | L40: 1936 | M40: 0.29103491 | N40: 7 | O40: 35.075 | P40: 21.401275 | Q40: 1936 | R40: 0.21887081 | S40: 5
A41: 20.67 | B41: 11.376583 | C41: 13.14 | E41: 20.67 | F41: 11.376583 | G41: -24.98 | J41: 35.526 | K41: 21.732675 | L41: 1935 | M41: 0.4231054 | N41: 11 | O41: 35.373 | P41: 21.620146 | Q41: 1935 | R41: 0.49872045 | S41: 13
A42: 20.74 | B42: 11.422211 | C42: 5.4 | E42: 20.74 | F42: 11.422211 | G42: -24.68 | J42: 36.1 | K42: 22.155781 | L42: 1934 | M42: 0.2342947 | N42: 6 | O42: 36.05 | P42: 22.118866 | Q42: 1934 | R42: 0.19872978 | S42: 5
A43: 20.8 | B43: 11.461349 | C43: 8.62 | E43: 20.8 | F43: 11.461349 | G43: -24.27 | J43: 36.417 | K43: 22.390075 | L43: 1933 | M43: 0.30517068 | N43: 8 | O43: 36.319 | P43: 22.317596 | Q43: 1933 | R43: 0.3413164 | S43: 9
A44: 20.85 | B44: 11.493984 | C44: 8.16 | E44: 20.85 | F44: 11.493984 | G44: -24.42 | J44: 36.829 | K44: 22.695246 | L44: 1932 | M44: 0.25314144 | N44: 7 | O44: 36.78 | P44: 22.658913 | Q44: 1932 | R44: 0.2545545 | S44: 7
A45: 20.9 | B45: 11.526637 | C45: 6.38 | E45: 20.9 | F45: 11.526637 | G45: -25.34 | J45: 37.17 | K45: 22.948388 | L45: 1931 | M45: 0.45408772 | N45: 13 | O45: 37.123 | P45: 22.913467 | Q45: 1931 | R45: 0.42191113 | S45: 12
A46: 20.95 | B46: 11.559308 | C46: 4.46 | E46: 20.95 | F46: 11.559308 | G46: -25.56 | J46: 37.78 | K46: 23.402475 | L46: 1930 | M46: 0.39358317 | N46: 11 | O46: 37.69 | P46: 23.335378 | Q46: 1930 | R46: 0.3395671 | S46: 10
A47: 21 | B47: 11.591997 | C47: 3.02 | E47: 21 | F47: 11.591997 | G47: -25.86 | J47: 38.307 | K47: 23.796058 | L47: 1929 | M47: 0.24630516 | N47: 7 | O47: 38.145 | P47: 23.674945 | Q47: 1929 | R47: 0.29699893 | S47: 8
A48: 21.05 | B48: 11.624704 | C48: 5.46 | D48: 1967 | E48: 21.05 | F48: 11.624704 | G48: -24.31 | H48: 1967 | J48: 38.636 | K48: 24.042364 | L48: 1928 | M48: 0.17621045 | N48: 5 | O48: 38.542 | P48: 23.971944 | Q48: 1928 | R48: 0.21136926 | S48: 6
A49: 21.11 | B49: 11.663976 | C49: 7.36 | E49: 21.11 | F49: 11.663976 | G49: -22.2 | J49: 38.871 | K49: 24.218574 | L49: 1927 | M49: 0.17644097 | N49: 5 | O49: 38.824 | P49: 24.183313 | Q49: 1927 | R49: 0.17639496 | S49: 5
A50: 21.17 | B50: 11.703274 | C50: 5.84 | E50: 21.17 | F50: 11.703274 | G50: -22.43 | J50: 39.106 | K50: 24.395015 | L50: 1926 | M50: 0.27374824 | N50: 7 | O50: 39.059 | P50: 24.359708 | Q50: 1926 | R50: 0.30905482 | S50: 8
A51: 21.22 | B51: 11.736041 | C51: 5.12 | E51: 21.22 | F51: 11.736041 | G51: -22.91 | J51: 39.47 | K51: 24.668763 | L51: 1925 | M51: 0.33917966 | N51: 9 | O51: 39.47 | P51: 24.668763 | Q51: 1925 | R51: 0.30145204 | S51: 8
...

Sheet ann accum dust
A1: Core: Dye 2 (Raven) Greenland 1998 | E1: Core A
E3: accum w.e
B4: depth firn | C4: depth w.e. | D4: year | E4: dust | F4: no. samples
B6: 19.95 | C6: 10.909356 | D6: 1969 | E6: 0.42814552 | F6: 10
B7: 20.61 | C7: 11.337501 | D7: 1968 | E7: 0.28720221 | F7: 8
B8: 21.05 | C8: 11.624704 | D8: 1967 | E8: 0.37411903 | F8: 11
B9: 21.62 | C9: 11.998823 | D9: 1966 | E9: 0.42277766 | F9: 12
B10: 22.26 | C10: 12.4216 | D10: 1965 | E10: 0.30494123 | F10: 9
B11: 22.719 | C11: 12.726542 | D11: 1964 | E11: 0.34784723 | F11: 10
B12: 23.24 | C12: 13.074389 | D12: 1963 | E12: 0.27096588 | F12: 8
B13: 23.644 | C13: 13.345355 | D13: 1962 | E13: 0.33074329 | F13: 10
B14: 24.135 | C14: 13.676098 | D14: 1961 | E14: 0.44564325 | F14: 14
B15: 24.793 | C15: 14.121741 | D15: 1960 | E15: 0.23610272 | F15: 7
B16: 25.14 | C16: 14.357844 | D16: 1959 | E16: 0.13095789 | F16: 4
B17: 25.332 | C17: 14.488802 | D17: 1958 | E17: 0.098366316 | F17: 3
... B258: 119.238 | C258: 93.081849 | D258: 1717 | E258: 0.388314 | F258: 9
B259: 119.661 | C259: 93.470163 | D259: 1716

Sheet ann accum O18
A1: Core: Dye 2 (Raven) Greenland 1998 | E1: Core A
E3: accum w.e.
B4: depth firn | C4: depth w.e. | D4: year | E4: O18 (m) | F4: no. samples
B6: 20.015 | C6: 10.951378 | D6: 1969 | E6: 0.34056163 | F6: 8
B7: 20.54 | C7: 11.29194 | D7: 1968 | E7: 0.3327638 | F7: 9
B8: 21.05 | C8: 11.624704 | D8: 1967 | E8: 0.242587 | F8: 7
B9: 21.42 | C9: 11.867291 | D9: 1966 | E9: 0.51455412 | F9: 15
B10: 22.2 | C10: 12.381845 | D10: 1965 | E10: 0.27680876 | F10: 8
B11: 22.617 | C11: 12.658654 | D11: 1964 | E11: 0.31540227 | F11: 9
B12: 23.09 | C12: 12.974056 | D12: 1963 | E12: 0.37129888 | F12: 11
B13: 23.644 | C13: 13.345355 | D13: 1962 | E13: 0.20392109 | F13: 6
B14: 23.947 | C14: 13.549276 | D14: 1961 | E14: 0.4129942 | F14: 13
B15: 24.558 | C15: 13.96227 | D15: 1960 | E15: 0.26484287 | F15: 8
B16: 24.948 | C16: 14.227113 | D16: 1959 | E16: 0.16344937 | F16: 5
B17: 25.188 | C17: 14.390562 | D17: 1958 | E17: 0.098239615 | F17: 3
... B259: 119.614 | C259: 93.427017 | D259: 1716 | E259: 0.384642 | F259: 9
B260: 120.033 | C260: 93.811659 | D260: 1715

Sheet ann avg data
A1: Core: Dye 2 (Raven) Greenland 1998 | E1: Core A
G2: accum w.e. | H2: ann. avg. | I2: accum w.e. | K2: annual
B3: year | C3: dust flux | D3: dust flux | E3: dust flux | G3: dust | H3: O18 | I3: O18 | K3: avg accum
C4: small | D4: total | E4: large | F4: cf | G4: mm w.e. | I4: mm w.e. | K4: dust & O18
B6: 1969 | C6: 7810 | D6: 19406 | E6: 2109 | F6: 31 | G6: =('ann accum dust'!E6*1000) -> 428.14552 | H6: -25.71 | I6: =('ann accum O18'!E6*1000) -> 340.56163 | K6: =AVERAGE(G6,I6) -> 384.35357
B7: 1968 | C7: 2969 | D7: 7442 | E7: 1006 | F7: 37 | G7: =('ann accum dust'!E7*1000) -> 287.20221 | H7: -25.2 | I7: =('ann accum O18'!E7*1000) -> 332.7638 | K7: =AVERAGE(G7,I7) -> 309.98301
B8: 1967 | C8: 2227 | D8: 5299 | E8: 646 | F8: 36 | G8: =('ann accum dust'!E8*1000) -> 374.11903 | H8: -23.68 | I8: =('ann accum O18'!E8*1000) -> 242.587 | K8: =AVERAGE(G8,I8) -> 308.35301
B9: 1966 | C9: 2362 | D9: 5300 | E9: 399 | F9: 28 | G9: =('ann accum dust'!E9*1000) -> 422.77766 | H9: -25.63 | I9: =('ann accum O18'!E9*1000) -> 514.55412 | K9: =AVERAGE(G9,I9) -> 468.66589
B10: 1965 | C10: 2606 | D10: 6890 | E10: 635 | F10: 35 | G10: =('ann accum dust'!E10*1000) -> 304.94123 | H10: -26.26 | I10: =('ann accum O18'!E10*1000) -> 276.80876 | K10: =AVERAGE(G10,I10) -> 290.875
B11: 1964 | C11: 5361 | D11: 9063 | E11: 531 | F11: 25 | G11: =('ann accum dust'!E11*1000) -> 347.84723 | H11: -25.71 | I11: =('ann accum O18'!E11*1000) -> 315.40227 | K11: =AVERAGE(G11,I11) -> 331.62475
B12: 1963 | C12: 6018 | D12: 11612 | E12: 676 | F12: 24 | G12: =('ann accum dust'!E12*1000) -> 270.96588 | H12: -25.02 | I12: =('ann accum O18'!E12*1000) -> 371.29888 | K12: =AVERAGE(G12,I12) -> 321.13238
B13: 1962 | C13: 2225 | D13: 4366 | E13: 194 | F13: 25 | G13: =('ann accum dust'!E13*1000) -> 330.74329 | H13: -27.24 | I13: =('ann accum O18'!E13*1000) -> 203.92109 | K13: =AVERAGE(G13,I13) -> 267.33219
B14: 1961 | C14: 2333 | D14: 4831 | E14: 447 | F14: 30 | G14: =('ann accum dust'!E14*1000) -> 445.64325 | H14: -25.06 | I14: =('ann accum O18'!E14*1000) -> 412.9942 | K14: =AVERAGE(G14,I14) -> 429.31873
B15: 1960 | C15: 1897 | D15: 4733 | E15: 526 | F15: 33 | G15: =('ann accum dust'!E15*1000) -> 236.10272 | H15: -25.51 | I15: =('ann accum O18'!E15*1000) -> 264.84287 | K15: =AVERAGE(G15,I15) -> 250.47279
B16: 1959 | C16: 2749 | D16: 6728 | E16: 534 | F16: 32 | G16: =('ann accum dust'!E16*1000) -> 130.95789 | H16: -26.67 | I16: =('ann accum O18'!E16*1000) -> 163.44937 | K16: =AVERAGE(G16,I16) -> 147.20363
B17: 1958 | C17: 3599 | D17: 9117 | E17: 1159 | F17: 34 | G17: =('ann accum dust'!E17*1000) -> 98.366316 | H17: -26.55 | I17: =('ann accum O18'!E17*1000) -> 98.239615 | K17: =AVERAGE(G17,I17) -> 98.302966
... B258: 1717 | C258: 5755 | D258: 12388 | E258: 724 | F258: 28 | G258: =('ann accum dust'!E258*1000) -> 388.314 | H258: -26.02 | I258: =('ann accum O18'!E258*1000) -> 431.46 | K258: =AVERAGE(G258,I258) -> 409.887
B259: 1716 | H259: -24.94 | I259: =('ann accum O18'!E259*1000) -> 384.642 | K259: =AVERAGE(G259,I259) -> 384.642
B261: avg. | D261: =AVERAGE(D6:D259) -> 12629.103 | G261: =AVERAGE(G6:G259) -> 326.3273 | H261: =AVERAGE(H6:H259) -> -26.423661 | I261: =AVERAGE(I6:I259) -> 326.22158 | K261: =AVERAGE(K6:K259) -> 326.38923
B264: Small = 0.63 - 0.83 um
B265: Large = >1.59 um
B266: Total >0.63 um

Sheet density data
A1: Core: Dye 2 (Raven) Greenland 1998
A3: Core A | B3: Core A | C3: Core B | D3: Core B
A4: mid point | B4: density | C4: mid point | D4: density
A5: depth (m) | B5: (kg/m3) | C5: depth (m) | D5: (kg/m3) | F5: Core A
A6: 0.65 | B6: 388.09 | C6: 0.46 | D6: 340.61 | F6: coefficients for depth-
A7: 1.805 | B7: 496.63 | C7: 1.465 | D7: 447.76 | F7: density polynomial
A8: 2.855 | B8: 429.15 | C8: 2.54 | D8: 424.22 | F8: A | G8: 407.1547
A9: 3.925 | B9: 551.22 | C9: 3.555 | D9: 492.69 | F9: B | G9: 18.2643
A10: 4.955 | B10: 441.67 | C10: 4.555 | D10: 481.72 | F10: C | G10: -0.42116
A11: 5.96 | B11: 467.18 | C11: 5.595 | D11: 469.74 | F11: D | G11: 0.00622613
A12: 6.91 | B12: 513.9 | C12: 6.625 | D12: 537.61 | F12: E | G12: -4.764729e-05
A13: 7.885 | B13: 507.63 | C13: 7.585 | D13: 572.84 | F13: F | G13: 1.41E-07
A14: 8.94 | B14: 553.91 | C14: 8.525 | D14: 519.28 | F14: R2 | G14: 0.9689
A15: 10.005 | B15: 586.54 | C15: 9.515 | D15: 501.13
A16: 11.05 | B16: 534.9 | C16: 10.52 | D16: 571.05 | F16: Core B
A17: 12.065 | B17: 561.78 | C17: 11.535 | D17: 579.08 | F17: coefficients for depth-
A18: 13.085 | B18: 576.56 | C18: 12.545 | D18: 610.02 | F18: density polynomial
A19: 14.105 | B19: 571.51 | C19: 13.545 | D19: 578.5 | F19: A | G19: 329.2295
A20: 15.14 | B20: 648.71 | C20: 14.525 | D20: 611.09 | F20: B | G20: 66.3845
A21: 16.14 | B21: 593.21 | C21: 15.5 | D21: 630.98 | F21: C | G21: -9.1268
A22: 17.12 | B22: 612.98 | C22: 16.485 | D22: 619.47 | F22: D | G22: 0.60411
A23: 18.14 | B23: 645.78 | C23: 17.495 | D23: 662.47 | F23: E | G23: -0.013339
A24: 19.175 | B24: 637.83 | C24: 18.54 | D24: 672.79 | F24: R2 | G24: 0.927
A25: 20.22 | B25: 651.56 | C25: 19.56 | D25: 661.93
A26: 21.26 | B26: 675.21
A27: 22.305 | B27: 662.34
A28: 23.36 | B28: 675.19
A29: 24.39 | B29: 694.76
A30: 25.425 | B30: 744.48
A31: 26.465 | B31: 650.65
A32: 27.475 | B32: 679.21
A33: 28.435 | B33: 750.91
A34: 29.465 | B34: 721.18
A35: 30.54 | B35: 732.94
A36: 31.56 | B36: 688.87
A37: 32.595 | B37: 690.1
... A105: 119.635 | B105: 912.94

Sheet W.E. depth calculation
A1: Core: Dye 2 (Raven) Greenland 1998 | E1: Core A
D3: density | E3: depths
C4: mid pt | D4: OSU model | E4: Core depth | F4: Sample
A5: depth (m) | B5: ss (cm) | C5: depth m | D5: OSU measured | E5: w.e. m | F5: w.e. cm
A6: 18.65 | B6: 6.1 | C6: =(A6)+(B6/200) -> 18.6805 | D6: =#REF!+(#REF!*C6)+(#REF!*(C6^2))+(#REF!*(C6^3))+(#REF!*(C6^4))+(#REF!*(C6^5)) -> #REF! | E6: 10.012 | F6: =B6*(D6/1000) -> #REF! | H6: coefficients for depth-
A7: 18.711 | B7: 5.1 | C7: =(A7)+(B7/200) -> 18.7365 | D7: =#REF!+(#REF!*C7)+(#REF!*(C7^2))+(#REF!*(C7^3))+(#REF!*(C7^4))+(#REF!*(C7^5)) -> #REF! | E7: =E6+(F6/100) -> #REF! | F7: =B7*(D7/1000) -> #REF! | H7: density polynomial
A8: 18.762 | B8: 5.1 | C8: =(A8)+(B8/200) -> 18.7875 | D8: =#REF!+(#REF!*C8)+(#REF!*(C8^2))+(#REF!*(C8^3))+(#REF!*(C8^4))+(#REF!*(C8^5)) -> #REF! | E8: =E7+(F7/100) -> #REF! | F8: =B8*(D8/1000) -> #REF! | H8: A | I8: 407.1547
A9: 18.813 | B9: 5.1 | C9: =(A9)+(B9/200) -> 18.8385 | D9: =#REF!+(#REF!*C9)+(#REF!*(C9^2))+(#REF!*(C9^3))+(#REF!*(C9^4))+(#REF!*(C9^5)) -> #REF! | E9: =E8+(F8/100) -> #REF! | F9: =B9*(D9/1000) -> #REF! | H9: B | I9: 18.2643
A10: 18.864 | B10: 5.1 | C10: =(A10)+(B10/200) -> 18.8895 | D10: =#REF!+(#REF!*C10)+(#REF!*(C10^2))+(#REF!*(C10^3))+(#REF!*(C10^4))+(#REF!*(C10^5)) -> #REF! | E10: =E9+(F9/100) -> #REF! | F10: =B10*(D10/1000) -> #REF! | H10: C | I10: -0.4212
A11: 18.915 | B11: 5.1 | C11: =(A11)+(B11/200) -> 18.9405 | D11: =#REF!+(#REF!*C11)+(#REF!*(C11^2))+(#REF!*(C11^3))+(#REF!*(C11^4))+(#REF!*(C11^5)) -> #REF! | E11: =E10+(F10/100) -> #REF! | F11: =B11*(D11/1000) -> #REF! | H11: D | I11: 0.00623
A12: 18.966 | B12: 5.1 | C12: =(A12)+(B12/200) -> 18.9915 | D12: =#REF!+(#REF!*C12)+(#REF!*(C12^2))+(#REF!*(C12^3))+(#REF!*(C12^4))+(#REF!*(C12^5)) -> #REF! | E12: =E11+(F11/100) -> #REF! | F12: =B12*(D12/1000) -> #REF! | H12: E | I12: -4.765e-05
A13: 19.017 | B13: 5.1 | C13: =(A13)+(B13/200) -> 19.0425 | D13: =#REF!+(#REF!*C13)+(#REF!*(C13^2))+(#REF!*(C13^3))+(#REF!*(C13^4))+(#REF!*(C13^5)) -> #REF! | E13: =E12+(F12/100) -> #REF! | F13: =B13*(D13/1000) -> #REF! | H13: F | I13: 1.41e-07
A14: 19.068 | B14: 5.1 | C14: =(A14)+(B14/200) -> 19.0935 | D14: =#REF!+(#REF!*C14)+(#REF!*(C14^2))+(#REF!*(C14^3))+(#REF!*(C14^4))+(#REF!*(C14^5)) -> #REF! | E14: =E13+(F13/100) -> #REF! | F14: =B14*(D14/1000) -> #REF! | H14: R2 | I14: 0.9689
A15: 19.119 | B15: 5.1 | C15: =(A15)+(B15/200) -> 19.1445 | D15: =#REF!+(#REF!*C15)+(#REF!*(C15^2))+(#REF!*(C15^3))+(#REF!*(C15^4))+(#REF!*(C15^5)) -> #REF! | E15: =E14+(F14/100) -> #REF! | F15: =B15*(D15/1000) -> #REF!
A16: 19.17 | B16: 5 | C16: =(A16)+(B16/200) -> 19.195 | D16: =#REF!+(#REF!*C16)+(#REF!*(C16^2))+(#REF!*(C16^3))+(#REF!*(C16^4))+(#REF!*(C16^5)) -> #REF! | E16: =E15+(F15/100) -> #REF! | F16: =B16*(D16/1000) -> #REF! | H16: Notes:
A17: 19.22 | B17: 5 | C17: =(A17)+(B17/200) -> 19.245 | D17: =#REF!+(#REF!*C17)+(#REF!*(C17^2))+(#REF!*(C17^3))+(#REF!*(C17^4))+(#REF!*(C17^5)) -> #REF! | E17: =E16+(F16/100) -> #REF! | F17: =B17*(D17/1000) -> #REF! | H17: 1) w.e. calculations (left)
A18: 19.27 | B18: 5 | C18: =(A18)+(B18/200) -> 19.295 | D18: =#REF!+(#REF!*C18)+(#REF!*(C18^2))+(#REF!*(C18^3))+(#REF!*(C18^4))+(#REF!*(C18^5)) -> #REF! | E18: =E17+(F17/100) -> #REF! | F18: =B18*(D18/1000) -> #REF! | H18: use the modeled density
A19: 19.32 | B19: 6 | C19: =(A19)+(B19/200) -> 19.35 | D19: =#REF!+(#REF!*C19)+(#REF!*(C19^2))+(#REF!*(C19^3))+(#REF!*(C19^4))+(#REF!*(C19^5)) -> #REF! | E19: =E18+(F18/100) -> #REF! | F19: =B19*(D19/1000) -> #REF! | H19: based on the depth at the mid-point of the sample
A20: 19.38 | B20: 6 | C20: =(A20)+(B20/200) -> 19.41 | D20: =#REF!+(#REF!*C20)+(#REF!*(C20^2))+(#REF!*(C20^3))+(#REF!*(C20^4))+(#REF!*(C20^5)) -> #REF! | E20: =E19+(F19/100) -> #REF! | F20: =B20*(D20/1000) -> #REF! | H20: 2) The depth at the top of the core (10.012 m.w.e.)
A21: 19.44 | B21: 5 | C21: =(A21)+(B21/200) -> 19.465 | D21: =#REF!+(#REF!*C21)+(#REF!*(C21^2))+(#REF!*(C21^3))+(#REF!*(C21^4))+(#REF!*(C21^5)) -> #REF! | E21: =E20+(F20/100) -> #REF! | F21: =B21*(D21/1000) -> #REF! | H21: is determined from the w.e. depth of the sample
A22: 19.49 | B22: 5 | C22: =(A22)+(B22/200) -> 19.515 | D22: =#REF!+(#REF!*C22)+(#REF!*(C22^2))+(#REF!*(C22^3))+(#REF!*(C22^4))+(#REF!*(C22^5)) -> #REF! | E22: =E21+(F21/100) -> #REF! | F22: =B22*(D22/1000) -> #REF! | H22: at the comparable depth in the overlapping
A23: 19.54 | B23: 5 | C23: =(A23)+(B23/200) -> 19.565 | D23: =#REF!+(#REF!*C23)+(#REF!*(C23^2))+(#REF!*(C23^3))+(#REF!*(C23^4))+(#REF!*(C23^5)) -> #REF! | E23: =E22+(F22/100) -> #REF! | F23: =B23*(D23/1000) -> #REF! | H23: Core B.
A24: 19.59 | B24: 5 | C24: =(A24)+(B24/200) -> 19.615 | D24: =#REF!+(#REF!*C24)+(#REF!*(C24^2))+(#REF!*(C24^3))+(#REF!*(C24^4))+(#REF!*(C24^5)) -> #REF! | E24: =E23+(F23/100) -> #REF! | F24: =B24*(D24/1000) -> #REF! | H24: 3) Note that the density model is used down to the depth of
A25: 19.64 | B25: 6 | C25: =(A25)+(B25/200) -> 19.67 | D25: =#REF!+(#REF!*C25)+(#REF!*(C25^2))+(#REF!*(C25^3))+(#REF!*(C25^4))+(#REF!*(C25^5)) -> #REF! | E25: =E24+(F24/100) -> #REF! | F25: =B25*(D25/1000) -> #REF! | H25: 116.781 meters where density is set to the constant value of 918.0
A26: 19.7 | B26: 7 | C26: =(A26)+(B26/200) -> 19.735 | D26: =#REF!+(#REF!*C26)+(#REF!*(C26^2))+(#REF!*(C26^3))+(#REF!*(C26^4))+(#REF!*(C26^5)) -> #REF! | E26: =E25+(F25/100) -> #REF! | F26: =B26*(D26/1000) -> #REF!
A27: 19.77 | B27: 7 | C27: =(A27)+(B27/200) -> 19.805 | D27: =#REF!+(#REF!*C27)+(#REF!*(C27^2))+(#REF!*(C27^3))+(#REF!*(C27^4))+(#REF!*(C27^5)) -> #REF! | E27: =E26+(F26/100) -> #REF! | F27: =B27*(D27/1000) -> #REF!
A28: 19.84 | B28: 5.5 | C28: =(A28)+(B28/200) -> 19.8675 | D28: =#REF!+(#REF!*C28)+(#REF!*(C28^2))+(#REF!*(C28^3))+(#REF!*(C28^4))+(#REF!*(C28^5)) -> #REF! | E28: =E27+(F27/100) -> #REF! | F28: =B28*(D28/1000) -> #REF!
A29: 19.895 | B29: 5.5 | C29: =(A29)+(B29/200) -> 19.9225 | D29: =#REF!+(#REF!*C29)+(#REF!*(C29^2))+(#REF!*(C29^3))+(#REF!*(C29^4))+(#REF!*(C29^5)) -> #REF! | E29: =E28+(F28/100) -> #REF! | F29: =B29*(D29/1000) -> #REF!
A30: 19.95 | B30: 6.5 | C30: =(A30)+(B30/200) -> 19.9825 | D30: =#REF!+(#REF!*C30)+(#REF!*(C30^2))+(#REF!*(C30^3))+(#REF!*(C30^4))+(#REF!*(C30^5)) -> #REF! | E30: =E29+(F29/100) -> #REF! | F30: =B30*(D30/1000) -> #REF!
A31: 20.015 | B31: 6.5 | C31: =(A31)+(B31/200) -> 20.0475 | D31: =#REF!+(#REF!*C31)+(#REF!*(C31^2))+(#REF!*(C31^3))+(#REF!*(C31^4))+(#REF!*(C31^5)) -> #REF! | E31: =E30+(F30/100) -> #REF! | F31: =B31*(D31/1000) -> #REF!
A32: 20.08 | B32: 6.5 | C32: =(A32)+(B32/200) -> 20.1125 | D32: =#REF!+(#REF!*C32)+(#REF!*(C32^2))+(#REF!*(C32^3))+(#REF!*(C32^4))+(#REF!*(C32^5)) -> #REF! | E32: =E31+(F31/100) -> #REF! | F32: =B32*(D32/1000) -> #REF!
A33: 20.145 | B33: 6 | C33: =(A33)+(B33/200) -> 20.175 | D33: =#REF!+(#REF!*C33)+(#REF!*(C33^2))+(#REF!*(C33^3))+(#REF!*(C33^4))+(#REF!*(C33^5)) -> #REF! | E33: =E32+(F32/100) -> #REF! | F33: =B33*(D33/1000) -> #REF!
A34: 20.205 | B34: 6.5 | C34: =(A34)+(B34/200) -> 20.2375 | D34: =#REF!+(#REF!*C34)+(#REF!*(C34^2))+(#REF!*(C34^3))+(#REF!*(C34^4))+(#REF!*(C34^5)) -> #REF! | E34: =E33+(F33/100) -> #REF! | F34: =B34*(D34/1000) -> #REF!
A35: 20.27 | B35: 7 | C35: =(A35)+(B35/200) -> 20.305 | D35: =#REF!+(#REF!*C35)+(#REF!*(C35^2))+(#REF!*(C35^3))+(#REF!*(C35^4))+(#REF!*(C35^5)) -> #REF! | E35: =E34+(F34/100) -> #REF! | F35: =B35*(D35/1000) -> #REF!
A36: 20.34 | B36: 6.5 | C36: =(A36)+(B36/200) -> 20.3725 | D36: =#REF!+(#REF!*C36)+(#REF!*(C36^2))+(#REF!*(C36^3))+(#REF!*(C36^4))+(#REF!*(C36^5)) -> #REF! | E36: =E35+(F35/100) -> #REF! | F36: =B36*(D36/1000) -> #REF!
A37: 20.405 | B37: 6.5 | C37: =(A37)+(B37/200) -> 20.4375 | D37: =#REF!+(#REF!*C37)+(#REF!*(C37^2))+(#REF!*(C37^3))+(#REF!*(C37^4))+(#REF!*(C37^5)) -> #REF! | E37: =E36+(F36/100) -> #REF! | F37: =B37*(D37/1000) -> #REF!
... A1969: 116.731 | B1969: 5 | C1969: =(A1969)+(B1969/200) -> 116.756 | D1969: =#REF!+(#REF!*C1969)+(#REF!*(C1969^2))+(#REF!*(C1969^3))+(#REF!*(C1969^4))+(#REF!*(C1969^5)) -> #REF! | E1969: =E1968+(F1968/100) -> #REF! | F1969: =B1969*(D1969/1000) -> #REF!
A1970: 116.781 | B1970: 5 | C1970: =(A1970)+(B1970/200) -> 116.806 | D1970: 918 | E1970: =E1969+(F1969/100) -> #REF! | F1970: =B1970*(D1970/1000) -> 4.59
A1971: 116.831 | B1971: 5 | C1971: =(A1971)+(B1971/200) -> 116.856 | D1971: 918 | E1971: =E1970+(F1970/100) -> #REF! | F1971: =B1971*(D1971/1000) -> 4.59
A1972: 116.881 | B1972: 5 | C1972: =(A1972)+(B1972/200) -> 116.906 | D1972: 918 | E1972: =E1971+(F1971/100) -> #REF! | F1972: =B1972*(D1972/1000) -> 4.59
...

Sheet Stratigrapy
A1: Core: Dye 2 (Raven) Greenland 1998 | E1: Core A
B3: depth from | C3: stratigraphic | E3: Note:
B4: top | C4: feature | E4: The type of statigraphic feature
E5: is noted at the bottom of
B6: 18.65 | E6: the stratigraphic unit
B7: 18.7 | C7: firn | E7: For example, the firn
B8: 18.74 | C8: ice layer | E8: feature to the left is from
B9: 18.78 | C9: firn | E9: 18.650 to 18.7 meters
B10: 18.79 | C10: ice layer | E10: in the core.
B11: 18.93 | C11: firn
B12: 18.95 | C12: ice layer | E12: * L.d.h. indicates a low density depth hoar layer
B13: 19.04 | C13: firn
B14: 19.05 | C14: ice layer
B15: 19.08 | C15: firn
B16: 19.11 | C16: lens
B17: 19.15 | C17: firn
B18: 19.16 | C18: lens
B19: 19.18 | C19: firn
B20: 19.21 | C20: lens
B21: 19.24 | C21: firn
B22: 19.25 | C22: ice layer
B23: 19.3 | C23: firn
B24: 19.31 | C24: ice layer
... B2181: 119.94 | C2181: ice

Sheet Beta Data
A1: Core: Dye 2 (Raven) Greenland 1998 | E1: Core A | F1: this file contains all information needed to calculate beta radioactivity per sample | U1: (in order by depth)
A3: Raw data | L3: Blank data | T3: Computed beta conc. dph/kg
A5: sample | B5: depth at | C5: sample | D5: month | E5: day | F5: hour | G5: minute | H5: count | I5: mass | J5: run time | L5: sample | M5: month | N5: day | O5: hour | P5: minute | Q5: count | R5: run time | T5: sample | U5: depth (m) | V5: sample | W5: beta conc.
A6: number | B6: top (m) | C6: size (cm) | I6: (kg) | J6: (minutes) | L6: number | R6: (minutes) | T6: number | V6: size(cm) | W6: (dph/kg)
A8: 101 | B8: 19.7 | C8: =(B9-B8)*100 -> 17.5 | D8: 3 | E8: 25 | F8: 22 | G8: 0 | H8: 167 | I8: 247 | J8: 500 | L8: 1 | M8: 3 | N8: 10 | O8: 16 | P8: 20 | Q8: 105 | R8: 500 | T8: 101 | U8: 19.7 | V8: 17.5 | W8: 101.826
A9: =+A8+1 -> 102 | B9: 19.875 | C9: =(B10-B9)*100 -> 17.5 | D9: 3 | E9: 26 | F9: 11 | G9: 0 | H9: 147 | I9: 265 | J9: 500 | L9: 2 | M9: 3 | N9: 15 | O9: 8 | P9: 0 | Q9: 89 | R9: 500 | T9: =+T8+1 -> 102 | U9: 19.875 | V9: 17.5 | W9: 63.007
A10: =+A9+1 -> 103 | B10: 20.05 | C10: =(B11-B10)*100 -> 17.5 | D10: 3 | E10: 26 | F10: 20 | G10: 40 | H10: 234 | I10: 285 | J10: 500 | L10: 3 | M10: 3 | N10: 18 | O10: 8 | P10: 15 | Q10: 115 | R10: 500 | T10: =+T9+1 -> 103 | U10: 20.05 | V10: 17.5 | W10: 187.621
A11: =+A10+1 -> 104 | B11: 20.225 | C11: =(B12-B11)*100 -> 17.5 | D11: 3 | E11: 27 | F11: 8 | G11: 0 | H11: 189 | I11: 255 | J11: 500 | L11: 4 | M11: 3 | N11: 20 | O11: 17 | P11: 0 | Q11: 94 | R11: 500 | T11: =+T10+1 -> 104 | U11: 20.225 | V11: 17.5 | W11: 135.1
A12: =+A11+1 -> 105 | B12: 20.4 | C12: =(B13-B12)*100 -> 17.5 | D12: 3 | E12: 28 | F12: 8 | G12: 0 | H12: 183 | I12: 230 | J12: 500 | L12: 5 | M12: 3 | N12: 22 | O12: 17 | P12: 0 | Q12: 123 | R12: 500 | T12: =+T11+1 -> 105 | U12: 20.4 | V12: 17.5 | W12: 151.622
A13: =+A12+1 -> 106 | B13: 20.575 | C13: =(B14-B13)*100 -> 16.5 | D13: 3 | E13: 28 | F13: 17 | G13: 0 | H13: 185 | I13: 204 | J13: 500 | L13: 6 | M13: 3 | N13: 24 | O13: 17 | P13: 0 | Q13: 102 | R13: 500 | T13: =+T12+1 -> 106 | U13: 20.575 | V13: 16.5 | W13: 175.091
A14: =+A13+1 -> 107 | B14: 20.74 | C14: =(B15-B14)*100 -> 17.5 | D14: 3 | E14: 29 | F14: 7 | G14: 20 | H14: 174 | I14: 213 | J14: 500 | L14: 7 | M14: 3 | N14: 27 | O14: 10 | P14: 10 | Q14: 113 | R14: 500 | T14: =+T13+1 -> 107 | U14: 20.74 | V14: 17.5 | W14: 145.863
A15: =+A14+1 -> 108 | B15: 20.915 | C15: =(B16-B15)*100 -> 17.5 | D15: 3 | E15: 29 | F15: 17 | G15: 10 | H15: 176 | I15: 223 | J15: 500 | L15: 8 | M15: 3 | N15: 30 | O15: 17 | P15: 0 | Q15: 88 | R15: 500 | T15: =+T14+1 -> 108 | U15: 20.915 | V15: 17.5 | W15: 143.113
A16: =+A15+1 -> 109 | B16: 21.09 | C16: =(B17-B16)*100 -> 17.5 | D16: 3 | E16: 30 | F16: 8 | G16: 0 | H16: 180 | I16: 213 | J16: 500 | L16: 9 | M16: 4 | N16: 1 | O16: 23 | P16: 10 | Q16: 107 | R16: 500 | T16: =+T15+1 -> 109 | U16: 21.09 | V16: 17.5 | W16: 157.77
A17: =+A16+1 -> 110 | B17: 21.265 | C17: =(B18-B17)*100 -> 17.5 | D17: 3 | E17: 31 | F17: 8 | G17: 0 | H17: 157 | I17: 248 | J17: 500 | L17: 10 | M17: 4 | N17: 4 | O17: 17 | P17: 30 | Q17: 95 | R17: 500 | T17: =+T16+1 -> 110 | U17: 21.265 | V17: 17.5 | W17: 101.415
A18: =+A17+1 -> 111 | B18: 21.44 | C18: =(B19-B18)*100 -> 17 | D18: 3 | E18: 31 | F18: 17 | G18: 0 | H18: 263 | I18: 277 | J18: 500 | L18: 11 | M18: 4 | N18: 7 | O18: 17 | P18: 0 | Q18: 101 | R18: 500 | T18: =+T17+1 -> 111 | U18: 21.44 | V18: 17 | W18: 252.554
A19: =+A18+1 -> 112 | B19: 21.61 | C19: =(B20-B19)*100 -> 17 | D19: 4 | E19: 1 | F19: 8 | G19: 10 | H19: 571 | I19: 261 | J19: 500 | L19: 12 | M19: 4 | N19: 12 | O19: 17 | P19: 0 | Q19: 100 | R19: 500 | T19: =+T18+1 -> 112 | U19: 21.61 | V19: 17 | W19: 766.86
A20: =+A19+1 -> 113 | B20: 21.78 | C20: =(B21-B20)*100 -> 17.5 | D20: 4 | E20: 2 | F20: 10 | G20: 0 | H20: 759 | I20: 238 | J20: 500 | L20: 13 | M20: 4 | N20: 15 | O20: 21 | P20: 0 | Q20: 97 | R20: 500 | T20: =+T19+1 -> 113 | U20: 21.78 | V20: 17.5 | W20: 1168.653
... A26: =+A25+1 -> 119 | B26: 22.83 | C26: =(B27-B26)*100 -> 17.5 | D26: 4 | E26: 5 | F26: 17 | G26: 17 | H26: 740 | I26: 241 | J26: 500 | L26: 19 | M26: 4 | N26: 30 | O26: 10 | P26: 0 | Q26: 97 | R26: 500 | T26: =+T25+1 -> 119 | U26: 22.83 | V26: 17.5 | W26: 1126.042
A27: =+A26+1 -> 120 | B27: 23.005 | C27: =(B28-B27)*100 -> 17.5 | D27: 4 | E27: 6 | F27: 9 | G27: 9 | H27: 787 | I27: 252 | J27: 500 | T27: =+T26+1 -> 120 | U27: 23.005 | V27: 17.5 | W27: 1155.727
A28: =+A27+1 -> 121 | B28: 23.18 | C28: =(B29-B28)*100 -> 17.5 | D28: 4 | E28: 6 | F28: 17 | G28: 17 | H28: 828 | I28: 254 | J28: 500 | T28: =+T27+1 -> 121 | U28: 23.18 | V28: 17.5 | W28: 1214.859
A29: =+A28+1 -> 122 | B29: 23.355 | C29: =(B30-B29)*100 -> 17.5 | D29: 4 | E29: 7 | F29: 8 | G29: 8 | H29: 280 | I29: 242 | J29: 500 | T29: =+T28+1 -> 122 | U29: 23.355 | V29: 17.5 | W29: 317.902
A30: =+A29+1 -> 123 | B30: 23.53 | C30: =(B31-B30)*100 -> 18 | D30: 4 | E30: 8 | F30: 13 | G30: 13 | H30: 220 | I30: 249 | J30: 500 | T30: =+T29+1 -> 123 | U30: 23.53 | V30: 18 | W30: 202.864
A31: =+A30+1 -> 124 | B31: 23.71 | C31: =(B32-B31)*100 -> 18 | D31: 4 | E31: 9 | F31: 13 | G31: 13 | H31: 256 | I31: 247 | J31: 500 | T31: =+T30+1 -> 124 | U31: 23.71 | V31: 18 | W31: 266.115
A32: =+A31+1 -> 125 | B32: 23.89 | C32: =(B33-B32)*100 -> 17 | D32: 4 | E32: 9 | F32: 22 | G32: 20 | H32: 897 | I32: 252 | J32: 500 | T32: =+T31+1 -> 125 | U32: 23.89 | V32: 17 | W32: 1336.047 | X32: 1963
A33: =+A32+1 -> 126 | B33: 24.06 | C33: =(B34-B33)*100 -> 16.5 | D33: 4 | E33: 10 | F33: 8 | G33: 0 | H33: 253 | I33: 253 | J33: 500 | T33: =+T32+1 -> 126 | U33: 24.06 | V33: 16.5 | W33: 254.792
A34: =+A33+1 -> 127 | B34: 24.225 | C34: =(B35-B34)*100 -> 16.5 | D34: 4 | E34: 10 | F34: 17 | G34: 0 | H34: 319 | I34: 271 | J34: 500 | T34: =+T33+1 -> 127 | U34: 24.225 | V34: 16.5 | W34: 340.815
A35: =+A34+1 -> 128 | B35: 24.39 | C35: =(B36-B35)*100 -> 16.5 | D35: 4 | E35: 11 | F35: 8 | G35: 35 | H35: 295 | I35: 237 | J35: 500 | T35: =+T34+1 -> 128 | U35: 24.39 | V35: 16.5 | W35: 346.903
A36: =+A35+1 -> 129 | B36: 24.555 | C36: =(B37-B36)*100 -> 16.5 | D36: 4 | E36: 11 | F36: 17 | G36: 10 | H36: 225 | I36: 254 | J36: 500 | T36: =+T35+1 -> 129 | U36: 24.555 | V36: 16.5 | W36: 207.192
A37: =+A36+1 -> 130 | B37: 24.72 | C37: =(B38-B37)*100 -> 17 | D37: 4 | E37: 12 | F37: 8 | G37: 35 | H37: 443 | I37: 274 | J37: 500 | T37: =+T36+1 -> 130 | U37: 24.72 | V37: 17 | W37: 528.38
A38: =+A37+1 -> 131 | B38: 24.89 | C38: =(B39-B38)*100 -> 17.5 | D38: 4 | E38: 13 | F38: 8 | G38: 35 | H38: 346 | I38: 265 | J38: 500 | T38: =+T37+1 -> 131 | U38: 24.89 | V38: 17.5 | W38: 394.79
A39: =+A38+1 -> 132 | B39: 25.065 | C39: =(B40-B39)*100 -> 17.5 | D39: 4 | E39: 13 | F39: 17 | G39: 0 | H39: 153 | I39: 244 | J39: 500 | T39: =+T38+1 -> 132 | U39: 25.065 | V39: 17.5 | W39: 94.416
A40: =+A39+1 -> 133 | B40: 25.24 | C40: =(B41-B40)*100 -> 17.5 | D40: 4 | E40: 14 | F40: 12 | G40: 45 | H40: 263 | I40: 273 | J40: 500 | T40: =+T39+1 -> 133 | U40: 25.24 | V40: 17.5 | W40: 254.706
A41: =+A40+1 -> 134 | B41: 25.415 | C41: =(B42-B41)*100 -> 17.5 | D41: 4 | E41: 15 | F41: 12 | G41: 10 | H41: 191 | I41: 278 | J41: 500 | T41: =+T40+1 -> 134 | U41: 25.415 | V41: 17.5 | W41: 140.648
A42: =+A41+1 -> 135 | B42: 25.59 | C42: =(B43-B42)*100 -> 17 | D42: 4 | E42: 16 | F42: 10 | G42: 0 | H42: 338 | I42: 293 | J42: 500 | T42: =+T41+1 -> 135 | U42: 25.59 | V42: 17 | W42: 326.766
A43: =+A42+1 -> 136 | B43: 25.76 | C43: =(B44-B43)*100 -> 20 | D43: 4 | E43: 16 | F43: 23 | G43: 0 | H43: 645 | I43: 320 | J43: 500 | T43: =+T42+1 -> 136 | U43: 25.76 | V43: 20 | W43: 704.727
A44: =+A43+1 -> 137 | B44: 25.96 | C44: =(B45-B44)*100 -> 16.8 | D44: 4 | E44: 17 | F44: 8 | G44: 15 | H44: 254 | I44: 237 | J44: 500 | T44: =+T43+1 -> 137 | U44: 25.96 | V44: 16.8 | W44: 254.158
... A51: =+A50+1 -> 144 | B51: 27.138 | C51: =(B52-B51)*100 -> 16.8 | D51: 4 | E51: 22 | F51: 12 | G51: 20 | H51: 180 | I51: 237 | J51: 500 | T51: =+T50+1 -> 144 | U51: 27.138 | V51: 16.8 | W51: 131.984
A52: =+A51+1 -> 145 | B52: 27.306 | C52: =(B53-B52)*100 -> 16.8 | D52: 4 | E52: 22 | F52: 23 | G52: 0 | H52: 254 | I52: 263 | J52: 500 | T52: =+T51+1 -> 145 | U52: 27.306 | V52: 16.8 | W52: 237.872 | X52: 1952
A53: =+A52+1 -> 146 | B53: 27.474 | C53: =(B54-B53)*100 -> 16.6 | D53: 4 | E53: 23 | F53: 12 | G53: 20 | H53: 153 | I53: 271 | J53: 500 | T53: =+T52+1 -> 146 | U53: 27.474 | V53: 16.6 | W53: 73.31
A54: =+A53+1 -> 147 | B54: 27.64 | C54: =(B55-B54)*100 -> 16 | D54: 4 | E54: 24 | F54: 8 | G54: 0 | H54: 145 | I54: 264 | J54: 500 | T54: =+T53+1 -> 147 | U54: 27.64 | V54: 16 | W54: 90.465
...

Sheet chem samples
A1: Core: Dye 2 (Raven) Greenland 1998 | E1: Core A
A2: Tracy Mashiotta
A4: tube number | B4: depth top | D4: depth top | F4: sections | K4: depth top | L4: depth top | O4: depth top
A5: 1912 | B5: m firn | C5: ss firn | D5: m w.e. | E5: ss w.e. | F5: Cl (ppb) | G5: NO3 (ppb) | H5: SO4 (ppb) | I5: SS So4 | J5: EXS | K5: m w.e. | L5: m firn | M5: ss firn | N5: ss w.e. | O5: m w.e.
A6: 44 | B6: 44.17 | C6: 4.37 | D6: 28.184 | E6: 3.370741 | F6: 4.42 | G6: 30.11 | H6: 24.95 | I6: =0.103*F6 -> 0.45526 | J6: =H6-I6 -> 24.49474 | K6: 28.184 | L6: 44.17 | M6: 4.37 | N6: 3.370741 | O6: 28.184
B7: 44.214 | C7: 4.37 | D7: 28.217939 | E7: 3.3714672 | F7: 15.99 | G7: 120.4 | H7: 98.76 | I7: =0.103*F7 -> 1.64697 | J7: =H7-I7 -> 97.11303 | K7: 28.217939 | L7: 44.214 | M7: 4.37 | N7: 3.3714672 | O7: =O6+(N6/100) -> 28.217707
B8: 44.257 | C8: 4.37 | D8: 28.251113 | E8: 3.3721763 | F8: 32.66 | G8: 157.07 | H8: 89.04 | I8: =0.103*F8 -> 3.36398 | J8: =H8-I8 -> 85.67602 | K8: 28.251113 | L8: 44.257 | M8: 4.37 | N8: 3.3721763 | O8: =O7+(N7/100) -> 28.251422
B9: 44.301 | C9: 4.37 | D9: 28.285067 | E9: 3.3729014 | F9: 20.87 | G9: 109.7 | H9: 127.21 | I9: =0.103*F9 -> 2.14961 | J9: =H9-I9 -> 125.06039 | K9: 28.285067 | L9: 44.301 | M9: 4.37 | N9: 3.3729014 | O9: =O8+(N8/100) -> 28.285144
B10: 44.345 | C10: 4.37 | D10: 28.319027 | E10: 3.3736259 | F10: 17.72 | G10: 120.92 | H10: 156.75 | I10: =0.103*F10 -> 1.82516 | J10: =H10-I10 -> 154.92484 | K10: 28.319027 | L10: 44.345 | M10: 4.37 | N10: 3.3736259 | O10: =O9+(N9/100) -> 28.318873
B11: 44.389 | C11: 4.37 | D11: 28.352995 | E11: 3.37435 | F11: 23.87 | G11: 131.29 | H11: 235.55 | I11: =0.103*F11 -> 2.45861 | J11: =H11-I11 -> 233.09139 | K11: 28.352995 | L11: 44.389 | M11: 4.37 | N11: 3.37435 | O11: =O10+(N10/100) -> 28.352609
B12: 44.432 | C12: 4.37 | D12: 28.386198 | E12: 3.375057 | F12: 13.53 | G12: 113.54 | H12: 225.2 | I12: =0.103*F12 -> 1.39359 | J12: =H12-I12 -> 223.80641 | K12: 28.386198 | L12: 44.432 | M12: 4.37 | N12: 3.375057 | O12: =O11+(N11/100) -> 28.386353
B13: 44.476 | C13: 4.37 | D13: 28.42018 | E13: 3.37578 | F13: 71.5 | G13: 176.18 | H13: 437.13 | I13: =0.103*F13 -> 7.3645 | J13: =H13-I13 -> 429.7655 | K13: 28.42018 | L13: 44.476 | M13: 4.37 | N13: 3.37578 | O13: =O12+(N12/100) -> 28.420103
B14: 44.52 | C14: 4.37 | D14: 28.45417 | E14: 3.3765024 | F14: 47.32 | G14: 128.28 | H14: 220.06 | I14: =0.103*F14 -> 4.87396 | J14: =H14-I14 -> 215.18604 | K14: 28.45417 | L14: 44.52 | M14: 4.37 | N14: 3.3765024 | O14: =O13+(N13/100) -> 28.453861
B15: 44.563 | C15: 4.37 | D15: 28.487394 | E15: 3.3772079 | F15: 4.21 | G15: 86.29 | H15: 80.73 | I15: =0.103*F15 -> 0.43363 | J15: =H15-I15 -> 80.29637 | K15: 28.487394 | L15: 44.563 | M15: 4.37 | N15: 3.3772079 | O15: =O14+(N14/100) -> 28.487626
B16: 44.607 | C16: 4.37 | D16: 28.521398 | E16: 3.3779293 | F16: 9.2 | G16: 143.08 | H16: 116.24 | I16: =0.103*F16 -> 0.9476 | J16: =H16-I16 -> 115.2924 | K16: 28.521398 | L16: 44.607 | M16: 4.37 | N16: 3.3779293 | O16: =O15+(N15/100) -> 28.521398
B17: 44.651 | C17: 4.37 | D17: 28.555409 | E17: 3.3786501 | F17: 50.85 | G17: 170.06 | H17: 377.44 | I17: =0.103*F17 -> 5.23755 | J17: =H17-I17 -> 372.20245 | K17: 28.555409 | L17: 44.651 | M17: 4.37 | N17: 3.3786501 | O17: =O16+(N16/100) -> 28.555177
B18: 44.694 | C18: 4.37 | D18: 28.588654 | E18: 3.3793541 | F18: 3.9 | G18: 54.98 | H18: 44.99 | I18: =0.103*F18 -> 0.4017 | J18: =H18-I18 -> 44.5883 | K18: 28.588654 | L18: 44.694 | M18: 4.37 | N18: 3.3793541 | O18: =O17+(N17/100) -> 28.588964
... B27: 45.1 | C27: 5 | D27: 28.902891 | E27: 3.8741147 | F27: 43.49 | G27: 43.1 | H27: 52.39 | I27: =0.103*F27 -> 4.47947 | J27: =H27-I27 -> 47.91053 | K27: 28.902891 | L27: 45.1 | M27: 5 | N27: 3.8741147 | O27: =O26+(N26/100) -> 28.902891
A28: 45 | B28: 45.15 | C28: 4.6 | D28: 28.941632 | E28: 3.5650407 | F28: 6.05 | G28: 67.63 | H28: 55.99 | I28: =0.103*F28 -> 0.62315 | J28: =H28-I28 -> 55.36685 | K28: 28.941632 | L28: 45.15 | M28: 4.6 | N28: 3.5650407 | O28: =O27+(N27/100) -> 28.941632
B29: 45.196 | C29: 4.6 | D29: 28.977283 | E29: 3.5658269 | F29: 4.13 | G29: 71.19 | H29: 70.5 | I29: =0.103*F29 -> 0.42539 | J29: =H29-I29 -> 70.07461 | K29: 28.977283 | L29: 45.196 | M29: 4.6 | N29: 3.5658269 | O29: =O28+(N28/100) -> 28.977283
B30: 45.242 | C30: 4.6 | D30: 29.012941 | E30: 3.5666126 | F30: 13.69 | G30: 140.12 | H30: 110.07 | I30: =0.103*F30 -> 1.41007 | J30: =H30-I30 -> 108.65993 | K30: 29.012941 | L30: 45.242 | M30: 4.6 | N30: 3.5666126 | O30: =O29+(N29/100) -> 29.012941
B31: 45.288 | C31: 4.6 | D31: 29.048607 | E31: 3.5673976 | F31: 25.68 | G31: 100.39 | H31: 128.57 | I31: =0.103*F31 -> 2.64504 | J31: =H31-I31 -> 125.92496 | K31: 29.048607 | L31: 45.288 | M31: 4.6 | N31: 3.5673976 | O31: =O30+(N30/100) -> 29.048607
B32: 45.334 | C32: 4.6 | D32: 29.084281 | E32: 3.568182 | F32: 55.15 | G32: 41.97 | H32: 81.97 | I32: =0.103*F32 -> 5.68045 | J32: =H32-I32 -> 76.28955 | K32: 29.084281 | L32: 45.334 | M32: 4.6 | N32: 3.568182 | O32: =O31+(N31/100) -> 29.084281
B33: 45.38 | C33: 4.6 | D33: 29.119963 | E33: 3.5689659 | F33: 35.22 | G33: 38.49 | H33: 70.03 | I33: =0.103*F33 -> 3.62766 | J33: =H33-I33 -> 66.40234 | K33: 29.119963 | L33: 45.38 | M33: 4.6 | N33: 3.5689659 | O33: =O32+(N32/100) -> 29.119963
B34: 45.426 | C34: 4.6 | D34: 29.155652 | E34: 3.5697491 | F34: 19.13 | G34: 39.61 | H34: 55.71 | I34: =0.103*F34 -> 1.97039 | J34: =H34-I34 -> 53.73961 | K34: 29.155652 | L34: 45.426 | M34: 4.6 | N34: 3.5697491 | O34: =O33+(N33/100) -> 29.155653
B35: 45.472 | C35: 4.6 | D35: 29.19135 | E35: 3.5705318 | F35: 4.81 | G35: 62.41 | H35: 92.46 | I35: =0.103*F35 -> 0.49543 | J35: =H35-I35 -> 91.96457 | K35: 29.19135 | L35: 45.472 | M35: 4.6 | N35: 3.5705318 | O35: =O34+(N34/100) -> 29.19135
B36: 45.518 | C36: 4.6 | D36: 29.227055 | E36: 3.5713139 | F36: 17.79 | G36: 46.84 | H36: 35.88 | I36: =0.103*F36 -> 1.83237 | J36: =H36-I36 -> 34.04763 | K36: 29.227055 | L36: 45.518 | M36: 4.6 | N36: 3.5713139 | O36: =O35+(N35/100) -> 29.227055
B37: 45.564 | C37: 4.6 | D37: 29.262768 | E37: 3.5720954 | F37: 12.04 | G37: 56.27 | H37: 39 | I37: =0.103*F37 -> 1.24012 | J37: =H37-I37 -> 37.75988 | K37: 29.262768 | L37: 45.564 | M37: 4.6 | N37: 3.5720954 | O37: =O36+(N36/100) -> 29.262768
B38: 45.61 | C38: 4.6 | D38: 29.298489 | E38: 3.5728764 | F38: 4.77 | G38: 59.32 | H38: 52.4 | I38: =0.103*F38 -> 0.49131 | J38: =H38-I38 -> 51.90869 | K38: 29.298489 | L38: 45.61 | M38: 4.6 | N38: 3.5728764 | O38: =O37+(N37/100) -> 29.298489
B39: 45.656 | C39: 4.6 | D39: 29.334218 | E39: 3.5736567 | F39: 14.66 | G39: 142.83 | H39: 264.78 | I39: =0.103*F39 -> 1.50998 | J39: =H39-I39 -> 263.27002 | K39: 29.334218 | L39: 45.656 | M39: 4.6 | N39: 3.5736567 | O39: =O38+(N38/100) -> 29.334218
B40: 45.702 | C40: 4.6 | D40: 29.369955 | E40: 3.5744365 | F40: 49.06 | G40: 103.63 | H40: 226.64 | I40: =0.103*F40 -> 5.05318 | J40: =H40-I40 -> 221.58682 | K40: 29.369955 | L40: 45.702 | M40: 4.6 | N40: 3.5744365 | O40: =O39+(N39/100) -> 29.369955
... B50: 46.162 | C50: 4.8 | D50: 29.727748 | E50: 3.7379508 | F50: 10.91 | G50: 68.94 | H50: 71.59 | I50: =0.103*F50 -> 1.12373 | J50: =H50-I50 -> 70.46627 | K50: 29.727748 | L50: 46.162 | M50: 4.8 | N50: 3.7379508 | O50: =O49+(N49/100) -> 29.727748
A51: 46 | B51: 46.21 | C51: 4.85 | D51: 29.765128 | E51: 3.7777388 | F51: 7.22 | G51: 110.84 | H51: 65.95 | I51: =0.103*F51 -> 0.74366 | J51: =H51-I51 -> 65.20634 | K51: 29.765128 | L51: 46.21 | M51: 4.85 | N51: 3.7777388 | O51: =O50+(N50/100) -> 29.765128
B52: 46.259 | C52: 4.85 | D52: 29.803295 | E52: 3.7786069 | F52: 16.62 | G52: 98.87 | H52: 99.54 | I52: =0.103*F52 -> 1.71186 | J52: =H52-I52 -> 97.82814 | K52: 29.803295 | L52: 46.259 | M52: 4.85 | N52: 3.7786069 | O52: =O51+(N51/100) -> 29.802905
B53: 46.307 | C53: 4.85 | D53: 29.840691 | E53: 3.7794566 | F53: 32.23 | G53: 52.2 | H53: 80.01 | I53: =0.103*F53 -> 3.31969 | J53: =H53-I53 -> 76.69031 | K53: 29.840691 | L53: 46.307 | M53: 4.85 | N53: 3.7794566 | O53: =O52+(N52/100) -> 29.840691
B54: 46.356 | C54: 4.85 | D54: 29.878875 | E54: 3.7803233 | F54: 24.53 | G54: 55.79 | H54: 56.97 | I54: =0.103*F54 -> 2.52659 | J54: =H54-I54 -> 54.44341 | K54: 29.878875 | L54: 46.356 | M54: 4.85 | N54: 3.7803233 | O54: =O53+(N53/100) -> 29.878486
B55: 46.404 | C55: 4.85 | D55: 29.916289 | E55: 3.7811717 | F55: 6.09 | G55: 34.38 | H55: 38.43 | I55: =0.103*F55 -> 0.62727 | J55: =H55-I55 -> 37.80273 | K55: 29.916289 | L55: 46.404 | M55: 4.85 | N55: 3.7811717 | O55: =O54+(N54/100) -> 29.916289
B56: 46.453 | C56: 4.85 | D56: 29.95449 | E56: 3.7820371 | F56: 9.38 | G56: 28.54 | H56: 25.87 | I56: =0.103*F56 -> 0.96614 | J56: =H56-I56 -> 24.90386 | K56: 29.95449 | L56: 46.453 | M56: 4.85 | N56: 3.7820371 | O56: =O55+(N55/100) -> 29.954101
B57: 46.501 | C57: 4.85 | D57: 29.991921 | E57: 3.7828842 | F57: 10.72 | G57: 31.23 | H57: 36.88 | I57: =0.103*F57 -> 1.10416 | J57: =H57-I57 -> 35.77584 | K57: 29.991921 | L57: 46.501 | M57: 4.85 | N57: 3.7828842 | O57: =O56+(N56/100) -> 29.991921
B58: 46.55 | C58: 4.85 | D58: 30.03014 | E58: 3.7837483 | F58: 6.8 | G58: 27.08 | H58: 28.43 | I58: =0.103*F58 -> 0.7004 | J58: =H58-I58 -> 27.7296 | K58: 30.03014 | L58: 46.55 | M58: 4.85 | N58: 3.7837483 | O58: =O57+(N57/100) -> 30.02975
...

Sheet chem ann data
A1: Core: Dye 2 (Raven) Greenland 1998 | E1: Core A
A3: not measured by OSU

Sheet core log
A1: Core: Dye 2 (Raven) Greenland 1998 | E1: Core A
